<?xml version="1.0"?>
<robot name="reto_robot">

    <material name="black">
        <color rgba="0 0 0 1"/>
    </material>
    <material name="white">
        <color rgba="1 1 1 1"/>
    </material>
    <link name="world"/>

    <link name="base_arm">
        <visual>
            <geometry>
                <cylinder length="0.6" radius="0.2"/>
            </geometry>
            <origin rpy="0 0 0" xyz="0 0 0.3"/>
            <material name="black"/>
        </visual>
    </link>
    
    <joint name="fixed" type="fixed">
        <parent link="world"/>
        <child link="base_arm"/>
    </joint>

    <link name="arm_1">
        <visual>
            <geometry>
                <box size="0.6 0.1 0.1"/>
            </geometry>
            <origin rpy="0 0 0" xyz="0.3 0 0"/>
            <material name="white"/>
        </visual>
    </link>

    <joint name="base_to_arm_1" type="revolute">
        <axis xyz="0 0 1"/>
        <limit effort="1000.0" lower="-0.5" upper="1.5" velocity="0.5"/>
        <origin rpy="1.57 0 0" xyz="0 -0.25 0.55"/>
        <parent link="base_arm"/>
        <child link="arm_1"/>
    </joint>

    <link name="arm_2">
        <visual>
            <geometry>
                <box size="0.3 0.1 0.1"/>
            </geometry>
            <origin rpy="0 0 0" xyz="0.15 0 0"/>
            <material name="white"/>
        </visual>
    </link>

    <joint name="arm_1_to_arm_2" type="revolute">
        <axis xyz="0 0 1"/>
        <limit effort="1000.0" lower="-0.5" upper="1.5" velocity="0.5"/>
        <origin rpy="0 0 0" xyz="0.55 0 -0.1"/>
        <parent link="arm_1"/>
        <child link="arm_2"/>
    </joint>
</robot>
